Workbook

Sheet Leia-me
B1: Calculadora de ROI Perfecting
B2: Versão 4.1 | Baseada no motor auditado v3.1-trajectory-1
B3: Workbook interativo: insira os dados da sua operação de vendas e obtenha ROI, payback e análise de risco em tempo real.
B7: O QUE ESTE WORKBOOK FAZ
B8: Projeta o retorno financeiro da adoção de horas de roleplay da Perfecting para suas equipes de vendas.
B9: Todas as células calculadas são fórmulas Excel — altere qualquer input e os resultados atualizam em tempo real.
B10: COMO USAR
B11: 1. Aba Premissas: revise e ajuste parâmetros globais (encargos, tiers de precificação, deltas de cenário, etc.).
B12: 2. Aba Equipes: insira a configuração da conta e dados por equipe (uma equipe por coluna C-L).
B13: 3. Aba Motor: cálculo automático — NÃO EDITE. Mostra detalhes por equipe.
B14: 4. Aba Conta: precificação consolidada, ROI, payback, série de 12 meses, verificação de realismo.
B15: 5. Aba Comparação de Cenários: veja os 3 cenários lado a lado (Conservador / Realista / Otimista).
... B38: Assentos
B39: Estimativas | C39: Receita, ticket, conversão, margem, rampa, novos contratados, gerentes, salário, ciclo são estimativas (não dados de clientes)
B40: Habilitação compartilhada
B41: Contratual

Sheet Tabela de Preços por Tier
B1: Tabela de Preços por Tier — Perfecting AI
B2: Referência rápida de preços por volume de horas
B3: Cliente: [inserir nome do cliente]
B5: TABELA DE PREÇOS POR HORA
B6: Tier | C6: Limite Superior (h/mês) | D6: Preço (R$/h) | E6: Economia vs Tier 1 | F6: Plano | G6: Horas/Assento/Mês | H6: Assentos Necessários
B7: Tier 1 | C7: ≤ 262 | D7: 98 | E7: — | F7: Intensivo | G7: 8 | H7: =ROUNDUP(262/8,0)
B8: Tier 2 | C8: 263 – 656 | D8: 82 | E8: =1-D8/D7 | F8: Padrão | G8: 4 | H8: =ROUNDUP(656/4,0)
B9: Tier 3 | C9: 657 – 1.243 | D9: 70 | E9: =1-D9/D7 | F9: Leve | G9: 2 | H9: =ROUNDUP(1243/2,0)
B10: Tier 4 | C10: > 1.243 | D10: 60 | E10: =1-D10/D7 | F10: Personalizado | G10: Variável | H10: =ROUNDUP(1243/8,0)

Sheet Premissas
B1: Premissas e Constantes
B2: Fonte: COGS V1 (ratificado 14/08) | Ajustável pelo usuário
B3: Parâmetros declarados e constantes fixas para o motor de cálculo. Células azul-amarelo são editáveis.
B6: PREMISSAS DECLARADAS — EDITÁVEIS
B7: Parâmetro | C7: Valor | E7: Observações | F7: Observações
B8: ENCARGOS (multiplicador trabalhista) | C8: 1.75 | E8: Cada R$1 de salário custa R$1,75 para a empresa
B9: JORNADA (horas úteis do gerente/mês) | C9: 200 | E9: Horas úteis de um gerente de treinamento por mês
B10: FATOR_ESCOPO (fallback) | C10: 2.1 | E10: Horas de gerente por hora de prática — usado quando declarado fora do intervalo
B11: SUPERVISAO (residual) | C11: 0.25 | E11: Tempo do gerente que continua necessário com a Perfecting
B12: HAIRCUT_RAMPA | C12: 0.7 | E12: Desconto anti-otimismo no ganho de rampa
B13: HAIRCUT_CICLO | C13: 0.7 | E13: Desconto anti-otimismo no ganho de ciclo
B14: HAIRCUT_CONVERSAO | C14: 0.7 | E14: Desconto anti-otimismo no ganho de conversão
B15: PCT_EVENTO_SUBSTITUIVEL | C15: 0.5 | E15: Fração de um evento presencial que é camada de prática
B17: CONSTANTES FIXAS [ratificado 14/08]
B18: Parâmetro | C18: Valor | E18: Observações | F18: Observações
B19: DIAS_UTEIS_MES | C19: 22 | E19: Dias úteis por mês
B20: DIAS_UTEIS_ANO | C20: 264 | E20: Dias úteis por ano
B21: TAXA_MINIMA (piso mensal) | C21: 13000 | E21: Mensalidade mínima para a conta
B22: Fator de escopo — mínimo | C22: 0.25
B23: Fator de escopo — máximo | C23: 6
B24: Receita/vendedor — mínimo esperado
B25: Receita/vendedor — máximo esperado
B26: Limite de verificação de realismo | C26: 0.25 | E26: Ganhos de performance / margem atual — limite
B28: ESCADA PROGRESSIVA (R$/hora, marginal por tier)
B29: Tier | C29: Limite superior (h/mês) | E29: R$/hora
B30: Tier 1 — até 262 h | C30: 262 | E30: 98
B31: Tier 2 — 263 a 573 h | C31: 573 | E31: 82
B32: Tier 3 — 574 a 1.243 h | C32: 1243 | E32: 70
B33: Tier 4 — acima de 1.243 h | C33: 999999999 | E33: 60
B35: PLANOS (definem consumo, não precificação)
B36: Plano | C36: Horas/assento/mês
B37: Essencial | C37: 2
B38: Padrão | C38: 4
B39: Intensivo | C39: 8
B41: CENÁRIOS (deltas predefinidos)
B42: Cenário | C42: Delta Ticket | D42: Delta Rampa | E42: Delta Ciclo | F42: Delta Conv (p.p.)
B43: Conservador | C43: 0.05 | D43: 0.2 | E43: 0.05 | F43: 0.5
B44: Realista | C44: 0.15 | D44: 0.5 | E44: 0.15 | F44: 2.5
B45: Otimista | C45: 0.2 | D45: 0.65 | E45: 0.2 | F45: 3.5
B47: CONTRATOS (duração compra garantias, não preço)
...

Sheet Equipes
B1: Equipes — Insira os Dados da Sua Operação de Vendas
B2: Preencha apenas as células amarelas | Fonte azul = seu input
B3: Insira uma equipe por coluna. Equipe sem vendedores é ignorada. Siga os passos numerados.
B6: CONFIGURAÇÃO DA CONTA
B7: Cenário da conta | L7: Conservador / Realista / Otimista
B8: Duração do contrato | L8: 3 / 6 / 12 / 24 months — buys guarantees, not discount
B9: Habilitação compartilhada? | L9: Yes = managers & counterfactual declared once, allocated by seller count
B10: Contratual da conta (se compartilhada) | L10: none / managers / external / event
B11: N. gerentes de treinamento (conta) | L11: allocated by number of sellers
B12: Horas treinamento/gerente/mês (conta) | L12: per manager — NOT allocated
B13: Salário mensal do gerente (conta) | L13: per manager — NOT allocated
B14: Custo anual treinamento externo (conta) | L14: allocated by number of sellers
B15: Custo anual evento presencial (conta) | L15: allocated by number of sellers
B17: EQUIPES — UMA POR COLUNA. Equipe sem vendedores é ignorada.
B18: Nome da equipe
B20: Passo 1 Estrutura da Equipe
B21: Número de vendedores
B22: Número de gerentes de treinamento
B23: Horas de treinamento por gerente/mês
B24: Vendedores cobertos por gerente/mês
B25: Horas de prática por vendedor coberto (hoje)
B26: Salário mensal do gerente
B28: Passo 2 Receita
B29: Receita mensal da equipe
B30: Ticket médio
... B57: Delta conversão p.p. ajuste fino (0-5 p.p.)

Sheet Motor
B1: Motor — Cálculos Automatizados
B2: NÃO EDITE | Todos os valores são fórmulas
B3: Cálculos detalhados por equipe. Resultados só aparecem quando a equipe está completa.
B6: PARÂMETROS DERIVADOS
B7: Equipe ativa? | C7: =Equipes!C21>0 | D7: =Equipes!D21>0 | E7: =Equipes!E21>0 | F7: =Equipes!F21>0 | G7: =Equipes!G21>0 | H7: =Equipes!H21>0 | I7: =Equipes!I21>0 | J7: =Equipes!J21>0 | ... L7: =Equipes!L21>0
B8: Proporção de vendedores (se habilitação compart.) | C8: =IF(Equipes!$C$9="Sim",IF(SUM(Equipes!$C21:$L21)>0,IF(Equipes!C21>0,Equipes!C21/SUM(Equipes!$C21:$L21),""),""),1) | D8: =IF(Equipes!$C$9="Sim",IF(SUM(Equipes!$C21:$L21)>0,IF(Equipes!D21>0,Equipes!D21/SUM(Equipes!$C21:$L21),""),""),1) | E8: =IF(Equipes!$C$9="Sim",IF(SUM(Equipes!$C21:$L21)>0,IF(Equipes!E21>0,Equipes!E21/SUM(Equipes!$C21:$L21),""),""),1) | F8: =IF(Equipes!$C$9="Sim",IF(SUM(Equipes!$C21:$L21)>0,IF(Equipes!F21>0,Equipes!F21/SUM(Equipes!$C21:$L21),""),""),1) | G8: =IF(Equipes!$C$9="Sim",IF(SUM(Equipes!$C21:$L21)>0,IF(Equipes!G21>0,Equipes!G21/SUM(Equipes!$C21:$L21),""),""),1) | H8: =IF(Equipes!$C$9="Sim",IF(SUM(Equipes!$C21:$L21)>0,IF(Equipes!H21>0,Equipes!H21/SUM(Equipes!$C21:$L21),""),""),1) | I8: =IF(Equipes!$C$9="Sim",IF(SUM(Equipes!$C21:$L21)>0,IF(Equipes!I21>0,Equipes!I21/SUM(Equipes!$C21:$L21),""),""),1) | J8: =IF(Equipes!$C$9="Sim",IF(SUM(Equipes!$C21:$L21)>0,IF(Equipes!J21>0,Equipes!J21/SUM(Equipes!$C21:$L21),""),""),1) | ... L8: =IF(Equipes!$C$9="Sim",IF(SUM(Equipes!$C21:$L21)>0,IF(Equipes!L21>0,Equipes!L21/SUM(Equipes!$C21:$L21),""),""),1)
B9: Gerentes de treinamento | C9: =IF(Equipes!$C$9="Sim",IF(AND(N(Equipes!$C$11)>0,ISNUMBER(C8)),Equipes!$C$11*C8,""),IF(Equipes!C22="","",Equipes!C22)) | D9: =IF(Equipes!$C$9="Sim",IF(AND(N(Equipes!$C$11)>0,ISNUMBER(D8)),Equipes!$C$11*D8,""),IF(Equipes!D22="","",Equipes!D22)) | E9: =IF(Equipes!$C$9="Sim",IF(AND(N(Equipes!$C$11)>0,ISNUMBER(E8)),Equipes!$C$11*E8,""),IF(Equipes!E22="","",Equipes!E22)) | F9: =IF(Equipes!$C$9="Sim",IF(AND(N(Equipes!$C$11)>0,ISNUMBER(F8)),Equipes!$C$11*F8,""),IF(Equipes!F22="","",Equipes!F22)) | G9: =IF(Equipes!$C$9="Sim",IF(AND(N(Equipes!$C$11)>0,ISNUMBER(G8)),Equipes!$C$11*G8,""),IF(Equipes!G22="","",Equipes!G22)) | H9: =IF(Equipes!$C$9="Sim",IF(AND(N(Equipes!$C$11)>0,ISNUMBER(H8)),Equipes!$C$11*H8,""),IF(Equipes!H22="","",Equipes!H22)) | I9: =IF(Equipes!$C$9="Sim",IF(AND(N(Equipes!$C$11)>0,ISNUMBER(I8)),Equipes!$C$11*I8,""),IF(Equipes!I22="","",Equipes!I22)) | J9: =IF(Equipes!$C$9="Sim",IF(AND(N(Equipes!$C$11)>0,ISNUMBER(J8)),Equipes!$C$11*J8,""),IF(Equipes!J22="","",Equipes!J22)) | ... L9: =IF(Equipes!$C$9="Sim",IF(AND(N(Equipes!$C$11)>0,ISNUMBER(L8)),Equipes!$C$11*L8,""),IF(Equipes!L22="","",Equipes!L22))
B10: Horas de treinamento/gerente/mês | C10: =IF(Equipes!$C$9="Sim",IF(Equipes!$C$12="","",Equipes!$C$12),IF(Equipes!C23="","",Equipes!C23)) | D10: =IF(Equipes!$C$9="Sim",IF(Equipes!$C$12="","",Equipes!$C$12),IF(Equipes!D23="","",Equipes!D23)) | E10: =IF(Equipes!$C$9="Sim",IF(Equipes!$C$12="","",Equipes!$C$12),IF(Equipes!E23="","",Equipes!E23)) | F10: =IF(Equipes!$C$9="Sim",IF(Equipes!$C$12="","",Equipes!$C$12),IF(Equipes!F23="","",Equipes!F23)) | G10: =IF(Equipes!$C$9="Sim",IF(Equipes!$C$12="","",Equipes!$C$12),IF(Equipes!G23="","",Equipes!G23)) | H10: =IF(Equipes!$C$9="Sim",IF(Equipes!$C$12="","",Equipes!$C$12),IF(Equipes!H23="","",Equipes!H23)) | I10: =IF(Equipes!$C$9="Sim",IF(Equipes!$C$12="","",Equipes!$C$12),IF(Equipes!I23="","",Equipes!I23)) | J10: =IF(Equipes!$C$9="Sim",IF(Equipes!$C$12="","",Equipes!$C$12),IF(Equipes!J23="","",Equipes!J23)) | ... L10: =IF(Equipes!$C$9="Sim",IF(Equipes!$C$12="","",Equipes!$C$12),IF(Equipes!L23="","",Equipes!L23))
B11: Salário mensal do gerente | C11: =IF(Equipes!$C$9="Sim",IF(Equipes!$C$13="","",Equipes!$C$13),IF(Equipes!C26="","",Equipes!C26)) | D11: =IF(Equipes!$C$9="Sim",IF(Equipes!$C$13="","",Equipes!$C$13),IF(Equipes!D26="","",Equipes!D26)) | E11: =IF(Equipes!$C$9="Sim",IF(Equipes!$C$13="","",Equipes!$C$13),IF(Equipes!E26="","",Equipes!E26)) | F11: =IF(Equipes!$C$9="Sim",IF(Equipes!$C$13="","",Equipes!$C$13),IF(Equipes!F26="","",Equipes!F26)) | G11: =IF(Equipes!$C$9="Sim",IF(Equipes!$C$13="","",Equipes!$C$13),IF(Equipes!G26="","",Equipes!G26)) | H11: =IF(Equipes!$C$9="Sim",IF(Equipes!$C$13="","",Equipes!$C$13),IF(Equipes!H26="","",Equipes!H26)) | I11: =IF(Equipes!$C$9="Sim",IF(Equipes!$C$13="","",Equipes!$C$13),IF(Equipes!I26="","",Equipes!I26)) | J11: =IF(Equipes!$C$9="Sim",IF(Equipes!$C$13="","",Equipes!$C$13),IF(Equipes!J26="","",Equipes!J26)) | ... L11: =IF(Equipes!$C$9="Sim",IF(Equipes!$C$13="","",Equipes!$C$13),IF(Equipes!L26="","",Equipes!L26))
B12: Tipo contratual | C12: =IF(Equipes!$C$9="Sim",IF(Equipes!$C$10="","",Equipes!$C$10),IF(Equipes!C40="","",Equipes!C40)) | D12: =IF(Equipes!$C$9="Sim",IF(Equipes!$C$10="","",Equipes!$C$10),IF(Equipes!D40="","",Equipes!D40)) | E12: =IF(Equipes!$C$9="Sim",IF(Equipes!$C$10="","",Equipes!$C$10),IF(Equipes!E40="","",Equipes!E40)) | F12: =IF(Equipes!$C$9="Sim",IF(Equipes!$C$10="","",Equipes!$C$10),IF(Equipes!F40="","",Equipes!F40)) | G12: =IF(Equipes!$C$9="Sim",IF(Equipes!$C$10="","",Equipes!$C$10),IF(Equipes!G40="","",Equipes!G40)) | H12: =IF(Equipes!$C$9="Sim",IF(Equipes!$C$10="","",Equipes!$C$10),IF(Equipes!H40="","",Equipes!H40)) | I12: =IF(Equipes!$C$9="Sim",IF(Equipes!$C$10="","",Equipes!$C$10),IF(Equipes!I40="","",Equipes!I40)) | J12: =IF(Equipes!$C$9="Sim",IF(Equipes!$C$10="","",Equipes!$C$10),IF(Equipes!J40="","",Equipes!J40)) | ... L12: =IF(Equipes!$C$9="Sim",IF(Equipes!$C$10="","",Equipes!$C$10),IF(Equipes!L40="","",Equipes!L40))
B13: Custo anual treinamento externo (conta) | C13: =IF(Equipes!$C$9="Sim",IF(AND(N(Equipes!$C$14)>0,ISNUMBER(C8)),Equipes!$C$14*C8,""),IF(Equipes!C41="","",Equipes!C41)) | D13: =IF(Equipes!$C$9="Sim",IF(AND(N(Equipes!$C$14)>0,ISNUMBER(D8)),Equipes!$C$14*D8,""),IF(Equipes!D41="","",Equipes!D41)) | E13: =IF(Equipes!$C$9="Sim",IF(AND(N(Equipes!$C$14)>0,ISNUMBER(E8)),Equipes!$C$14*E8,""),IF(Equipes!E41="","",Equipes!E41)) | F13: =IF(Equipes!$C$9="Sim",IF(AND(N(Equipes!$C$14)>0,ISNUMBER(F8)),Equipes!$C$14*F8,""),IF(Equipes!F41="","",Equipes!F41)) | G13: =IF(Equipes!$C$9="Sim",IF(AND(N(Equipes!$C$14)>0,ISNUMBER(G8)),Equipes!$C$14*G8,""),IF(Equipes!G41="","",Equipes!G41)) | H13: =IF(Equipes!$C$9="Sim",IF(AND(N(Equipes!$C$14)>0,ISNUMBER(H8)),Equipes!$C$14*H8,""),IF(Equipes!H41="","",Equipes!H41)) | I13: =IF(Equipes!$C$9="Sim",IF(AND(N(Equipes!$C$14)>0,ISNUMBER(I8)),Equipes!$C$14*I8,""),IF(Equipes!I41="","",Equipes!I41)) | J13: =IF(Equipes!$C$9="Sim",IF(AND(N(Equipes!$C$14)>0,ISNUMBER(J8)),Equipes!$C$14*J8,""),IF(Equipes!J41="","",Equipes!J41)) | ... L13: =IF(Equipes!$C$9="Sim",IF(AND(N(Equipes!$C$14)>0,ISNUMBER(L8)),Equipes!$C$14*L8,""),IF(Equipes!L41="","",Equipes!L41))
B14: Custo anual evento presencial (conta) | C14: =IF(Equipes!$C$9="Sim",IF(AND(N(Equipes!$C$15)>0,ISNUMBER(C8)),Equipes!$C$15*C8,""),IF(Equipes!C42="","",Equipes!C42)) | D14: =IF(Equipes!$C$9="Sim",IF(AND(N(Equipes!$C$15)>0,ISNUMBER(D8)),Equipes!$C$15*D8,""),IF(Equipes!D42="","",Equipes!D42)) | E14: =IF(Equipes!$C$9="Sim",IF(AND(N(Equipes!$C$15)>0,ISNUMBER(E8)),Equipes!$C$15*E8,""),IF(Equipes!E42="","",Equipes!E42)) | F14: =IF(Equipes!$C$9="Sim",IF(AND(N(Equipes!$C$15)>0,ISNUMBER(F8)),Equipes!$C$15*F8,""),IF(Equipes!F42="","",Equipes!F42)) | G14: =IF(Equipes!$C$9="Sim",IF(AND(N(Equipes!$C$15)>0,ISNUMBER(G8)),Equipes!$C$15*G8,""),IF(Equipes!G42="","",Equipes!G42)) | H14: =IF(Equipes!$C$9="Sim",IF(AND(N(Equipes!$C$15)>0,ISNUMBER(H8)),Equipes!$C$15*H8,""),IF(Equipes!H42="","",Equipes!H42)) | I14: =IF(Equipes!$C$9="Sim",IF(AND(N(Equipes!$C$15)>0,ISNUMBER(I8)),Equipes!$C$15*I8,""),IF(Equipes!I42="","",Equipes!I42)) | J14: =IF(Equipes!$C$9="Sim",IF(AND(N(Equipes!$C$15)>0,ISNUMBER(J8)),Equipes!$C$15*J8,""),IF(Equipes!J42="","",Equipes!J42)) | ... L14: =IF(Equipes!$C$9="Sim",IF(AND(N(Equipes!$C$15)>0,ISNUMBER(L8)),Equipes!$C$15*L8,""),IF(Equipes!L42="","",Equipes!L42))
B15: Equipe completa? | C15: =AND(Equipes!C21>0,N(C9)>0,N(C10)>0,Equipes!C24>0,Equipes!C25>0,N(C11)>0,Equipes!C29>0,Equipes!C30>0,Equipes!C31>0,Equipes!C32>0,Equipes!C35>0,Equipes!C36>0,Equipes!C50>0,Equipes!C49<>"",C12<>"",IF(C12="treinamento externo",N(C13)>0,TRUE())) | D15: =AND(Equipes!D21>0,N(D9)>0,N(D10)>0,Equipes!D24>0,Equipes!D25>0,N(D11)>0,Equipes!D29>0,Equipes!D30>0,Equipes!D31>0,Equipes!D32>0,Equipes!D35>0,Equipes!D36>0,Equipes!D50>0,Equipes!D49<>"",D12<>"",IF(D12="treinamento externo",N(D13)>0,TRUE())) | E15: =AND(Equipes!E21>0,N(E9)>0,N(E10)>0,Equipes!E24>0,Equipes!E25>0,N(E11)>0,Equipes!E29>0,Equipes!E30>0,Equipes!E31>0,Equipes!E32>0,Equipes!E35>0,Equipes!E36>0,Equipes!E50>0,Equipes!E49<>"",E12<>"",IF(E12="treinamento externo",N(E13)>0,TRUE())) | F15: =AND(Equipes!F21>0,N(F9)>0,N(F10)>0,Equipes!F24>0,Equipes!F25>0,N(F11)>0,Equipes!F29>0,Equipes!F30>0,Equipes!F31>0,Equipes!F32>0,Equipes!F35>0,Equipes!F36>0,Equipes!F50>0,Equipes!F49<>"",F12<>"",IF(F12="treinamento externo",N(F13)>0,TRUE())) | G15: =AND(Equipes!G21>0,N(G9)>0,N(G10)>0,Equipes!G24>0,Equipes!G25>0,N(G11)>0,Equipes!G29>0,Equipes!G30>0,Equipes!G31>0,Equipes!G32>0,Equipes!G35>0,Equipes!G36>0,Equipes!G50>0,Equipes!G49<>"",G12<>"",IF(G12="treinamento externo",N(G13)>0,TRUE())) | H15: =AND(Equipes!H21>0,N(H9)>0,N(H10)>0,Equipes!H24>0,Equipes!H25>0,N(H11)>0,Equipes!H29>0,Equipes!H30>0,Equipes!H31>0,Equipes!H32>0,Equipes!H35>0,Equipes!H36>0,Equipes!H50>0,Equipes!H49<>"",H12<>"",IF(H12="treinamento externo",N(H13)>0,TRUE())) | I15: =AND(Equipes!I21>0,N(I9)>0,N(I10)>0,Equipes!I24>0,Equipes!I25>0,N(I11)>0,Equipes!I29>0,Equipes!I30>0,Equipes!I31>0,Equipes!I32>0,Equipes!I35>0,Equipes!I36>0,Equipes!I50>0,Equipes!I49<>"",I12<>"",IF(I12="treinamento externo",N(I13)>0,TRUE())) | J15: =AND(Equipes!J21>0,N(J9)>0,N(J10)>0,Equipes!J24>0,Equipes!J25>0,N(J11)>0,Equipes!J29>0,Equipes!J30>0,Equipes!J31>0,Equipes!J32>0,Equipes!J35>0,Equipes!J36>0,Equipes!J50>0,Equipes!J49<>"",J12<>"",IF(J12="treinamento externo",N(J13)>0,TRUE())) | ... L15: =AND(Equipes!L21>0,N(L9)>0,N(L10)>0,Equipes!L24>0,Equipes!L25>0,N(L11)>0,Equipes!L29>0,Equipes!L30>0,Equipes!L31>0,Equipes!L32>0,Equipes!L35>0,Equipes!L36>0,Equipes!L50>0,Equipes!L49<>"",L12<>"",IF(L12="treinamento externo",N(L13)>0,TRUE()))
B17: Horas de prática declaradas/mês
B18: Horas de prática com Perfecting/mês | C18: =IF(Equipes!C49="","",IFERROR(INDEX(Premissas!$C$37:$C$39,MATCH(Equipes!C49,Premissas!$B$37:$B$39,0)),"")) | D18: =IF(Equipes!D49="","",IFERROR(INDEX(Premissas!$C$37:$C$39,MATCH(Equipes!D49,Premissas!$B$37:$B$39,0)),"")) | E18: =IF(Equipes!E49="","",IFERROR(INDEX(Premissas!$C$37:$C$39,MATCH(Equipes!E49,Premissas!$B$37:$B$39,0)),"")) | F18: =IF(Equipes!F49="","",IFERROR(INDEX(Premissas!$C$37:$C$39,MATCH(Equipes!F49,Premissas!$B$37:$B$39,0)),"")) | G18: =IF(Equipes!G49="","",IFERROR(INDEX(Premissas!$C$37:$C$39,MATCH(Equipes!G49,Premissas!$B$37:$B$39,0)),"")) | H18: =IF(Equipes!H49="","",IFERROR(INDEX(Premissas!$C$37:$C$39,MATCH(Equipes!H49,Premissas!$B$37:$B$39,0)),"")) | I18: =IF(Equipes!I49="","",IFERROR(INDEX(Premissas!$C$37:$C$39,MATCH(Equipes!I49,Premissas!$B$37:$B$39,0)),"")) | J18: =IF(Equipes!J49="","",IFERROR(INDEX(Premissas!$C$37:$C$39,MATCH(Equipes!J49,Premissas!$B$37:$B$39,0)),"")) | ... L18: =IF(Equipes!L49="","",IFERROR(INDEX(Premissas!$C$37:$C$39,MATCH(Equipes!L49,Premissas!$B$37:$B$39,0)),""))
B19: Assentos efetivos | C19: =IF(C15,MIN(Equipes!C50,Equipes!C21),"") | D19: =IF(D15,MIN(Equipes!D50,Equipes!D21),"") | E19: =IF(E15,MIN(Equipes!E50,Equipes!E21),"") | F19: =IF(F15,MIN(Equipes!F50,Equipes!F21),"") | G19: =IF(G15,MIN(Equipes!G50,Equipes!G21),"") | H19: =IF(H15,MIN(Equipes!H50,Equipes!H21),"") | I19: =IF(I15,MIN(Equipes!I50,Equipes!I21),"") | J19: =IF(J15,MIN(Equipes!J50,Equipes!J21),"") | ... L19: =IF(L15,MIN(Equipes!L50,Equipes!L21),"")
B20: Horas da equipe/mês | C20: =IF(C15,C19*C18,"") | D20: =IF(D15,D19*D18,"") | E20: =IF(E15,E19*E18,"") | F20: =IF(F15,F19*F18,"") | G20: =IF(G15,G19*G18,"") | H20: =IF(H15,H19*H18,"") | I20: =IF(I15,I19*I18,"") | J20: =IF(J15,J19*J18,"") | ... L20: =IF(L15,L19*L18,"")
B21: Custo do gerente por hora | C21: =IF(C15,C11*Premissas!$C$8/Premissas!$C$9,"") | D21: =IF(D15,D11*Premissas!$C$8/Premissas!$C$9,"") | E21: =IF(E15,E11*Premissas!$C$8/Premissas!$C$9,"") | F21: =IF(F15,F11*Premissas!$C$8/Premissas!$C$9,"") | G21: =IF(G15,G11*Premissas!$C$8/Premissas!$C$9,"") | H21: =IF(H15,H11*Premissas!$C$8/Premissas!$C$9,"") | I21: =IF(I15,I11*Premissas!$C$8/Premissas!$C$9,"") | J21: =IF(J15,J11*Premissas!$C$8/Premissas!$C$9,"") | ... L21: =IF(L15,L11*Premissas!$C$8/Premissas!$C$9,"")
B22: FATORES DE PERFORMANCE | C22: =IF(C15,Equipes!C29/Equipes!C21,"") | D22: =IF(D15,Equipes!D29/Equipes!D21,"") | E22: =IF(E15,Equipes!E29/Equipes!E21,"") | F22: =IF(F15,Equipes!F29/Equipes!F21,"") | G22: =IF(G15,Equipes!G29/Equipes!G21,"") | H22: =IF(H15,Equipes!H29/Equipes!H21,"") | I22: =IF(I15,Equipes!I29/Equipes!I21,"") | J22: =IF(J15,Equipes!J29/Equipes!J21,"") | ... L22: =IF(L15,Equipes!L29/Equipes!L21,"")
B23: Cobertura (assentos/vendedores, máx. 1) | C23: =IF(C15,C10*C9,"") | D23: =IF(D15,D10*D9,"") | E23: =IF(E15,E10*E9,"") | F23: =IF(F15,F10*F9,"") | G23: =IF(G15,G10*G9,"") | H23: =IF(H15,H10*H9,"") | I23: =IF(I15,I10*I9,"") | J23: =IF(J15,J10*J9,"") | ... L23: =IF(L15,L10*L9,"")
B24: Delta ticket efetivo | C24: =IF(C15,Equipes!C24*C9,"") | D24: =IF(D15,Equipes!D24*D9,"") | E24: =IF(E15,Equipes!E24*E9,"") | F24: =IF(F15,Equipes!F24*F9,"") | G24: =IF(G15,Equipes!G24*G9,"") | H24: =IF(H15,Equipes!H24*H9,"") | I24: =IF(I15,Equipes!I24*I9,"") | J24: =IF(J15,Equipes!J24*J9,"") | ... L24: =IF(L15,Equipes!L24*L9,"")
B25: Delta rampa efetivo | C25: =IF(C15,C24*Equipes!C25,"") | D25: =IF(D15,D24*Equipes!D25,"") | E25: =IF(E15,E24*Equipes!E25,"") | F25: =IF(F15,F24*Equipes!F25,"") | G25: =IF(G15,G24*Equipes!G25,"") | H25: =IF(H15,H24*Equipes!H25,"") | I25: =IF(I15,I24*Equipes!I25,"") | J25: =IF(J15,J24*Equipes!J25,"") | ... L25: =IF(L15,L24*Equipes!L25,"")
B27: Delta conversão efetivo (p.p.)
B28: Fator de escopo declarado | C28: =IF(C15,IF(C25>0,C23/C25,""),"") | D28: =IF(D15,IF(D25>0,D23/D25,""),"") | E28: =IF(E15,IF(E25>0,E23/E25,""),"") | F28: =IF(F15,IF(F25>0,F23/F25,""),"") | G28: =IF(G15,IF(G25>0,G23/G25,""),"") | H28: =IF(H15,IF(H25>0,H23/H25,""),"") | I28: =IF(I15,IF(I25>0,I23/I25,""),"") | J28: =IF(J15,IF(J25>0,J23/J25,""),"") | ... L28: =IF(L15,IF(L25>0,L23/L25,""),"")
B29: Fator de escopo fora do intervalo 0,25-6? | C29: =IF(C15,IF(ISNUMBER(C28),OR(C28<Premissas!$C$22,C28>Premissas!$C$23),TRUE()),FALSE()) | D29: =IF(D15,IF(ISNUMBER(D28),OR(D28<Premissas!$C$22,D28>Premissas!$C$23),TRUE()),FALSE()) | E29: =IF(E15,IF(ISNUMBER(E28),OR(E28<Premissas!$C$22,E28>Premissas!$C$23),TRUE()),FALSE()) | F29: =IF(F15,IF(ISNUMBER(F28),OR(F28<Premissas!$C$22,F28>Premissas!$C$23),TRUE()),FALSE()) | G29: =IF(G15,IF(ISNUMBER(G28),OR(G28<Premissas!$C$22,G28>Premissas!$C$23),TRUE()),FALSE()) | H29: =IF(H15,IF(ISNUMBER(H28),OR(H28<Premissas!$C$22,H28>Premissas!$C$23),TRUE()),FALSE()) | I29: =IF(I15,IF(ISNUMBER(I28),OR(I28<Premissas!$C$22,I28>Premissas!$C$23),TRUE()),FALSE()) | J29: =IF(J15,IF(ISNUMBER(J28),OR(J28<Premissas!$C$22,J28>Premissas!$C$23),TRUE()),FALSE()) | ... L29: =IF(L15,IF(ISNUMBER(L28),OR(L28<Premissas!$C$22,L28>Premissas!$C$23),TRUE()),FALSE())
B30: Fator de escopo utilizado | C30: =IF(C15,IF(C29,Premissas!$C$10,C28),"") | D30: =IF(D15,IF(D29,Premissas!$C$10,D28),"") | E30: =IF(E15,IF(E29,Premissas!$C$10,E28),"") | F30: =IF(F15,IF(F29,Premissas!$C$10,F28),"") | G30: =IF(G15,IF(G29,Premissas!$C$10,G28),"") | H30: =IF(H15,IF(H29,Premissas!$C$10,H28),"") | I30: =IF(I15,IF(I29,Premissas!$C$10,I28),"") | J30: =IF(J15,IF(J29,Premissas!$C$10,J28),"") | ... L30: =IF(L15,IF(L29,Premissas!$C$10,L28),"")
B31: Origem do fator | C31: =IF(C15,IF(C29,"premissa (2,1x)","DADOS DO CLIENTE"),"") | D31: =IF(D15,IF(D29,"premissa (2,1x)","DADOS DO CLIENTE"),"") | E31: =IF(E15,IF(E29,"premissa (2,1x)","DADOS DO CLIENTE"),"") | F31: =IF(F15,IF(F29,"premissa (2,1x)","DADOS DO CLIENTE"),"") | G31: =IF(G15,IF(G29,"premissa (2,1x)","DADOS DO CLIENTE"),"") | H31: =IF(H15,IF(H29,"premissa (2,1x)","DADOS DO CLIENTE"),"") | I31: =IF(I15,IF(I29,"premissa (2,1x)","DADOS DO CLIENTE"),"") | J31: =IF(J15,IF(J29,"premissa (2,1x)","DADOS DO CLIENTE"),"") | ... L31: =IF(L15,IF(L29,"premissa (2,1x)","DADOS DO CLIENTE"),"")
B33: COBERTURA E CUSTO MANUAL
B34: Cobertura (assentos/vendedores, máx. 1) | C34: =IF(C15,MIN(1,C19/Equipes!C21),"") | D34: =IF(D15,MIN(1,D19/Equipes!D21),"") | E34: =IF(E15,MIN(1,E19/Equipes!E21),"") | F34: =IF(F15,MIN(1,F19/Equipes!F21),"") | G34: =IF(G15,MIN(1,G19/Equipes!G21),"") | H34: =IF(H15,MIN(1,H19/Equipes!H21),"") | I34: =IF(I15,MIN(1,I19/Equipes!I21),"") | J34: =IF(J15,MIN(1,J19/Equipes!J21),"") | ... L34: =IF(L15,MIN(1,L19/Equipes!L21),"")
B35: Custo manual equivalente/mês | C35: =IF(C15,C20*C21*C30,"") | D35: =IF(D15,D20*D21*D30,"") | E35: =IF(E15,E20*E21*E30,"") | F35: =IF(F15,F20*F21*F30,"") | G35: =IF(G15,G20*G21*G30,"") | H35: =IF(H15,H20*H21*H30,"") | I35: =IF(I15,I20*I21*I30,"") | J35: =IF(J15,J20*J21*J30,"") | ... L35: =IF(L15,L20*L21*L30,"")
B36: Horas economizadas/mês (auto.) | C36: =IF(C15,C20*C30*(1-Premissas!$C$11),"") | D36: =IF(D15,D20*D30*(1-Premissas!$C$11),"") | E36: =IF(E15,E20*E30*(1-Premissas!$C$11),"") | F36: =IF(F15,F20*F30*(1-Premissas!$C$11),"") | G36: =IF(G15,G20*G30*(1-Premissas!$C$11),"") | H36: =IF(H15,H20*H30*(1-Premissas!$C$11),"") | I36: =IF(I15,I20*I30*(1-Premissas!$C$11),"") | J36: =IF(J15,J20*J30*(1-Premissas!$C$11),"") | ... L36: =IF(L15,L20*L30*(1-Premissas!$C$11),"")
B38: Economia de horas/mês
B39: Eficiência (R$/ano) | C39: =IF(C15,C20*C30*C21*(1-Premissas!$C$11)*12,"") | D39: =IF(D15,D20*D30*D21*(1-Premissas!$C$11)*12,"") | E39: =IF(E15,E20*E30*E21*(1-Premissas!$C$11)*12,"") | F39: =IF(F15,F20*F30*F21*(1-Premissas!$C$11)*12,"") | G39: =IF(G15,G20*G30*G21*(1-Premissas!$C$11)*12,"") | H39: =IF(H15,H20*H30*H21*(1-Premissas!$C$11)*12,"") | I39: =IF(I15,I20*I30*I21*(1-Premissas!$C$11)*12,"") | J39: =IF(J15,J20*J30*J21*(1-Premissas!$C$11)*12,"") | ... L39: =IF(L15,L20*L30*L21*(1-Premissas!$C$11)*12,"")
B40: Custo declarado do caminho (ano) | C40: =IF(C15,IF(C12="nenhum",0,IF(C12="gerentes",C10*C9*C21*(1-Premissas!$C$11)*12,IF(C12="treinamento externo",C13*(1-Premissas!$C$11),C14*Premissas!$C$15))),"") | D40: =IF(D15,IF(D12="nenhum",0,IF(D12="gerentes",D10*D9*D21*(1-Premissas!$C$11)*12,IF(D12="treinamento externo",D13*(1-Premissas!$C$11),D14*Premissas!$C$15))),"") | E40: =IF(E15,IF(E12="nenhum",0,IF(E12="gerentes",E10*E9*E21*(1-Premissas!$C$11)*12,IF(E12="treinamento externo",E13*(1-Premissas!$C$11),E14*Premissas!$C$15))),"") | F40: =IF(F15,IF(F12="nenhum",0,IF(F12="gerentes",F10*F9*F21*(1-Premissas!$C$11)*12,IF(F12="treinamento externo",F13*(1-Premissas!$C$11),F14*Premissas!$C$15))),"") | G40: =IF(G15,IF(G12="nenhum",0,IF(G12="gerentes",G10*G9*G21*(1-Premissas!$C$11)*12,IF(G12="treinamento externo",G13*(1-Premissas!$C$11),G14*Premissas!$C$15))),"") | H40: =IF(H15,IF(H12="nenhum",0,IF(H12="gerentes",H10*H9*H21*(1-Premissas!$C$11)*12,IF(H12="treinamento externo",H13*(1-Premissas!$C$11),H14*Premissas!$C$15))),"") | I40: =IF(I15,IF(I12="nenhum",0,IF(I12="gerentes",I10*I9*I21*(1-Premissas!$C$11)*12,IF(I12="treinamento externo",I13*(1-Premissas!$C$11),I14*Premissas!$C$15))),"") | J40: =IF(J15,IF(J12="nenhum",0,IF(J12="gerentes",J10*J9*J21*(1-Premissas!$C$11)*12,IF(J12="treinamento externo",J13*(1-Premissas!$C$11),J14*Premissas!$C$15))),"") | ... L40: =IF(L15,IF(L12="nenhum",0,IF(L12="gerentes",L10*L9*L21*(1-Premissas!$C$11)*12,IF(L12="treinamento externo",L13*(1-Premissas!$C$11),L14*Premissas!$C$15))),"")
B41: Eficiência (R$/ano) | C41: =IF(C15,MIN(C40,C39),"") | D41: =IF(D15,MIN(D40,D39),"") | E41: =IF(E15,MIN(E40,E39),"") | F41: =IF(F15,MIN(F40,F39),"") | G41: =IF(G15,MIN(G40,G39),"") | H41: =IF(H15,MIN(H40,H39),"") | I41: =IF(I15,MIN(I40,I39),"") | J41: =IF(J15,MIN(J40,J39),"") | ... L41: =IF(L15,MIN(L40,L39),"")
B42: Teto de eficiência ativo? | C42: =IF(C15,C40>C39,FALSE()) | D42: =IF(D15,D40>D39,FALSE()) | E42: =IF(E15,E40>E39,FALSE()) | F42: =IF(F15,F40>F39,FALSE()) | G42: =IF(G15,G40>G39,FALSE()) | H42: =IF(H15,H40>H39,FALSE()) | I42: =IF(I15,I40>I39,FALSE()) | J42: =IF(J15,J40>J39,FALSE()) | ... L42: =IF(L15,L40>L39,FALSE())
B44: Receita mensal
B45: Ticket médio | C45: =IF(C15,IF(Equipes!C53="",Premissas!$C$56,MIN(MAX(Equipes!C53,0),Premissas!$C$63)),"") | D45: =IF(D15,IF(Equipes!D53="",Premissas!$C$56,MIN(MAX(Equipes!D53,0),Premissas!$C$63)),"") | E45: =IF(E15,IF(Equipes!E53="",Premissas!$C$56,MIN(MAX(Equipes!E53,0),Premissas!$C$63)),"") | F45: =IF(F15,IF(Equipes!F53="",Premissas!$C$56,MIN(MAX(Equipes!F53,0),Premissas!$C$63)),"") | G45: =IF(G15,IF(Equipes!G53="",Premissas!$C$56,MIN(MAX(Equipes!G53,0),Premissas!$C$63)),"") | H45: =IF(H15,IF(Equipes!H53="",Premissas!$C$56,MIN(MAX(Equipes!H53,0),Premissas!$C$63)),"") | I45: =IF(I15,IF(Equipes!I53="",Premissas!$C$56,MIN(MAX(Equipes!I53,0),Premissas!$C$63)),"") | J45: =IF(J15,IF(Equipes!J53="",Premissas!$C$56,MIN(MAX(Equipes!J53,0),Premissas!$C$63)),"") | ... L45: =IF(L15,IF(Equipes!L53="",Premissas!$C$56,MIN(MAX(Equipes!L53,0),Premissas!$C$63)),"")
B46: Margem | C46: =IF(C15,IF(Equipes!C54="",Premissas!$C$57,MIN(MAX(Equipes!C54,0),Premissas!$C$64)),"") | D46: =IF(D15,IF(Equipes!D54="",Premissas!$C$57,MIN(MAX(Equipes!D54,0),Premissas!$C$64)),"") | E46: =IF(E15,IF(Equipes!E54="",Premissas!$C$57,MIN(MAX(Equipes!E54,0),Premissas!$C$64)),"") | F46: =IF(F15,IF(Equipes!F54="",Premissas!$C$57,MIN(MAX(Equipes!F54,0),Premissas!$C$64)),"") | G46: =IF(G15,IF(Equipes!G54="",Premissas!$C$57,MIN(MAX(Equipes!G54,0),Premissas!$C$64)),"") | H46: =IF(H15,IF(Equipes!H54="",Premissas!$C$57,MIN(MAX(Equipes!H54,0),Premissas!$C$64)),"") | I46: =IF(I15,IF(Equipes!I54="",Premissas!$C$57,MIN(MAX(Equipes!I54,0),Premissas!$C$64)),"") | J46: =IF(J15,IF(Equipes!J54="",Premissas!$C$57,MIN(MAX(Equipes!J54,0),Premissas!$C$64)),"") | ... L46: =IF(L15,IF(Equipes!L54="",Premissas!$C$57,MIN(MAX(Equipes!L54,0),Premissas!$C$64)),"")
B47: Vendas/mês | C47: =IF(C15,MIN(Equipes!C31,1),"") | D47: =IF(D15,MIN(Equipes!D31,1),"") | E47: =IF(E15,MIN(Equipes!E31,1),"") | F47: =IF(F15,MIN(Equipes!F31,1),"") | G47: =IF(G15,MIN(Equipes!G31,1),"") | H47: =IF(H15,MIN(Equipes!H31,1),"") | I47: =IF(I15,MIN(Equipes!I31,1),"") | J47: =IF(J15,MIN(Equipes!J31,1),"") | ... L47: =IF(L15,MIN(Equipes!L31,1),"")
...

Sheet Custo da Inação
B1: Custo da Inação (COI)
B2: Quanto custa NÃO investir em coaching contínuo para vendas | Baseado em pesquisa MySalesCoach 2026, Ebsta, Gartner, Dixon/McKenna HBR
B3: Este módulo expõe o GAP entre o coaching que acontece e o que deveria acontecer. Aditivo ao ROI — cria urgência antes da justificativa de investimento.
B6: DIMENSÃO 1 — GAP DE COBERTURA DE COACHING
B7: Parâmetro | C7: Valor | D7: Unidade | E7: Fonte / Observação
B8: Total de vendedores | C8: =IF(N(Conta!C43)>0,Conta!C43,0) | D8: vendedores | E8: Cross-reference da aba Conta
B9: Vendedores cobertos/mês (hoje) | C9: =IF(N(Motor!C23)>0,Motor!C23*Motor!C9,IF(N(Equipes!C24)>0,Equipes!C24*Motor!C9,N(Conta!C43)*0.28)) | D9: vendedores | E9: Só 28% recebem coaching semanal (MySalesCoach 2026). Fórmula: cobertos × horas_train
B10: Gap de cobertura de coaching | C10: =IF(AND(ISNUMBER(C8),C8>0),IF(ISNUMBER(C9),(C8-C9)/C8,1-0.28),) | D10: % | E10: Gap = (total - cobertos) / total. Se 100 vendedores e 28 cobertos → 72% gap
B11: Vendedores NÃO treinados/mês | C11: =IF(ISNUMBER(C8),IF(ISNUMBER(C9),C8-C9,C8*(1-0.28)),) | D11: vendedores | E11: Vendedores sem coaching regular
B13: DIMENSÃO 2 — PERDA DE RECEITA POR SUB-PERFORMANCE
B14: Parâmetro | C14: Valor | D14: Unidade | E14: Fonte / Observação
B15: Delta de atingimento de quota (quota attainment, semanal vs trimestral) | C15: 0.29 | D15: p.p. | E15: MySalesCoach 2026: 76% (semanal) vs 47% (trimestral) = 29pp gap. 3.700+ profissionais
B16: Haircut COI (conservador) | C16: 0.5 | E16: Desconto anti-otimismo: aplica 50% do delta. Mesma lógica dos haircuts do Motor
B17: Delta efetivo de attainment | C17: =C15*C16 | D17: p.p. | E17: Delta aplicado com haircut
B18: Receita média/vendedor/mês | C18: =IF(AND(ISNUMBER(Equipes!C29),Conta!C43>0),Equipes!C29/Conta!C43,) | D18: R$/mês | E18: Receita da equipe / total vendedores (cross-ref Equipes + Conta)
B19: Receita perdida/vendedor não treinado/mês | C19: =IF(AND(ISNUMBER(C18),ISNUMBER(C17)),C18*C17,) | D19: R$/mês | E19: receita_média × delta_efetivo (decimal)
B20: Receita perdida total/mês | C20: =IF(AND(ISNUMBER(C19),ISNUMBER(C11)),C19*C11,) | D20: R$/mês | E20: receita_perdida × vendedores_não_treinados
B21: COI Receita Anual | C21: =IF(ISNUMBER(C20),C20*12,) | D21: R$/ano | E21: Custo da inação em receita por sub-performance
B23: DIMENSÃO 3 — CUSTO DE RAMPA ESTENDIDA
B24: Parâmetro | C24: Valor | D24: Unidade | E24: Fonte / Observação
B25: Rampa média atual | C25: =IF(ISNUMBER(Equipes!C35),Equipes!C35,5.3) | D25: meses | E25: Dado do cliente ou benchmark: 5,3 meses (CareerTrainer.ai 2026)
B26: Extensão por falta de coaching | C26: 1.4 | D26: meses | E26: Ebsta 2024: rampa aumentou de 4,3 para 5,7 meses (1,4 meses adicionais)
B27: Haircut rampa COI | C27: 0.5 | E27: Desconto conservador: aplica 50% da extensão
B28: Meses adicionais efetivos | C28: =C26*C27 | D28: meses | E28: extensão × haircut
B29: Novos vendedores/ano | C29: =IF(ISNUMBER(Equipes!C36),Equipes!C36,N(Conta!C43)*0.2) | D29: vendedores | E29: Dado do cliente ou estimativa: ~20% turnover/ano
B30: Receita perdida/mês por vendedor em rampa | C30: =IF(ISNUMBER(C18),C18*0.5,) | D30: R$/mês | E30: Vendedor em rampa gera ~50% da receita plena (conservador)
B31: COI Rampa Anual | C31: =IF(AND(ISNUMBER(C28),ISNUMBER(C29),ISNUMBER(C30)),C28*C29*C30,) | D31: R$/ano | E31: meses_adicionais × novos_ano × receita_perdida_rampa
B33: DIMENSÃO 4 — CUSTO DE TURNOVER POR FALTA DE COACHING
B34: Parâmetro | C34: Valor | D34: Unidade | E34: Fonte / Observação
B35: Taxa de retenção com coaching frequente | C35: 0.74 | D35: % | E35: MySalesCoach 2026: 74% dos SDRs com coaching esperam ficar 12 meses
B36: Taxa de retenção sem coaching | C36: 0.34 | D36: % | E36: MySalesCoach 2026: apenas 34% sem coaching esperam ficar. Gap de 40pp
B37: Delta de attrition | C37: =C35-C36 | D37: p.p. | E37: Diferença de retenção entre com e sem coaching
B38: Taxa de turnover adicional | C38: =IF(ISNUMBER(C37),C37,) | D38: % | E38: Proporção extra de vendedores que saem por falta de coaching
B39: Salário mensal do vendedor | C39: =IF(ISNUMBER(Equipes!C37),Equipes!C37,0) | D39: R$/mês | E39: Dado do cliente (aba Equipes)
B40: Custo de substituição (multiplicador) | C40: 1 | D40: × salário | E40: Range: 50-150% do salário anual (SHRM/Gallup). 1× = conservador
B41: Custo por turnover | C41: =IF(AND(ISNUMBER(C39),ISNUMBER(C40)),C39*Premissas!C8*C40*12,) | D41: R$/pessoa | E41: salário × encargos × multiplicador × 12
B42: COI Turnover Anual | C42: =IF(AND(ISNUMBER(C38),ISNUMBER(C8),ISNUMBER(C41)),C38*C8*C41,) | D42: R$/ano | E42: turnover_adicional × vendedores_total × custo_por_turnover
B44: DIMENSÃO 5 — IMPOSTO DO APRENDIZADO EM VIVO (LIVE-LEARNING TAX)
B45: Parâmetro | C45: Valor | D45: Unidade | E45: Fonte / Observação
B46: Taxa de negócios perdidos por "sem decisão" (no decision / status quo) | C46: 0.5 | D46: % | E46: Dixon & McKenna HBR: 40-60% dos deals B2B perdidos para "no decision". 50% = ponto médio
...

Sheet Conta
B1: Conta — Precificação, ROI e Payback Consolidados
B2: Cálculo em tempo real | Resultados só aparecem quando todas as equipes ativas estão completas
B3: Precificação escalonada com piso, decomposição de valor, série de 12 meses, verificação de realismo e alerta de contrato.
B6: CONFIGURAÇÃO E STATUS
B7: Contrato | C7: =Equipes!$C8
B8: Meses | C8: =IFERROR(INDEX(Premissas!$C$49:$C$52,MATCH(Equipes!$C8,Premissas!$B$49:$B$52,0)),"")
B9: Desconto | C9: =IFERROR(INDEX(Premissas!$D$49:$D$52,MATCH(Equipes!$C8,Premissas!$B$49:$B$52,0)),0)
B10: Cenário | C10: =Equipes!$C7
B11: Equipes ativas | C11: =COUNTIF(Motor!C7:L7,TRUE())
B12: Equipes completas | C12: =COUNTIF(Motor!C15:L15,TRUE())
B13: Horas da conta (h/mês) | C13: =SUM(Motor!C20:L20)
B14: Conta completa? | C14: =AND($C$11>0,$C$11=$C$12)
B16: DETALHAMENTO DA PRECIFICAÇÃO ESCADONADA
B17: Tier 1 (até 262h) | C17: =MIN($C$13,Premissas!$C$30) | D17: =Premissas!$E$30 | E17: =C17*D17
B18: Tier 2 (263-573h) | C18: =MAX(0,MIN($C$13,Premissas!$C$31)-Premissas!$C$30) | D18: =Premissas!$E$31 | E18: =C18*D18
B19: Tier 3 (574-1243h) | C19: =MAX(0,MIN($C$13,Premissas!$C$32)-Premissas!$C$31) | D19: =Premissas!$E$32 | E19: =C19*D19
B20: Tier 4 (1244h+) | C20: =MAX(0,$C$13-Premissas!$C$32) | D20: =Premissas!$E$33 | E20: =C20*D20
B21: Preço bruto (mês) | C21: =SUM(E17:E20)
B22: MENSALIDADE (com piso) | C22: =IF($C$14,MAX($C$21*(1-$C$9),Premissas!$C$21),"")
B23: Piso ativo? (R$13.000) | C23: =IF($C$14,$C$21*(1-$C$9)<Premissas!$C$21,FALSE())
B24: Taxa efetiva (R$/h) | C24: =IF(AND(ISNUMBER($C$22),$C$13>0),$C$22/$C$13,"")
B25: Tier marginal (R$/h) | C25: =IF($C$13>Premissas!$C$32,Premissas!$E$33,IF($C$13>Premissas!$C$31,Premissas!$E$32,IF($C$13>Premissas!$C$30,Premissas!$E$31,Premissas!$E$30)))
B26: Investimento anual | C26: =IF(ISNUMBER($C$22),$C$22*12,"")
B28: RESULTADO CONSOLIDADO
B29: VALOR ANUAL DA CONTA | C29: =IF($C$14,SUM(Motor!C72:L72),"")
B30: ROI CONSOLIDADO
B31: PAYBACK (meses)
B32: Payback excede contrato? | C32: =IF(ISNUMBER($C$31),$C$31>$C$8,FALSE()) | E32: Auditoria A-01: payback usa investimento anualizado; contratos curtos podem mostrar payback > duração do contrato
B34: DECOMPOSIÇÃO DE VALOR
B35: Eficiência (ano) | C35: =IF($C$14,SUM(Motor!C41:L41),"")
B36: Ganho de ticket (ano) | C36: =IF($C$14,SUM(Motor!C60:L60),"")
B37: Margem de rampa (ano) | C37: =IF($C$14,SUM(Motor!C61:L61),"")
B38: Ganho de conversão (ano) | C38: =IF($C$14,SUM(Motor!C62:L62),"")
B39: Ganho de ciclo (ano) | C39: =IF($C$14,SUM(Motor!C68:L68),"")
B40: Verificação: soma = valor anual | C40: =IF($C$14,IF(ABS(SUM(C35:C39)-$C$29)<0.01,"OK","ERROR"),"")
B42: OPERAÇÕES CONSOLIDADAS
B43: Total de vendedores | C43: =IF($C$14,SUM(Equipes!C21:L21),"")
B44: Total de assentos efetivos | C44: =IF($C$14,SUM(Motor!C19:L19),"")
B45: Cobertura da conta | C45: =IF($C$14,MIN(1,$C$44/$C$43),"")
B46: Preço médio por assento (mês) | C46: =IF(AND(ISNUMBER($C$22),N($C$44)>0),$C$22/$C$44,"")
...

Sheet Comparação de Cenários
B1: Comparação de Cenários — Conservador / Realista / Otimista
B2: Todos os 3 cenários lado a lado | Baseado nos dados atuais das equipes
B3: Mostra como ROI, payback e valor mudam entre cenários. Usa mesmos dados da equipe; apenas deltas mudam.
B6: PARÂMETROS DE CENÁRIO
B7: Métrica | C7: Conservador | D7: Realista | E7: Otimista
B8: Delta ticket | C8: =Premissas!$C$43 | D8: =Premissas!$C$44 | E8: =Premissas!$C$45
B9: Delta rampa | C9: =Premissas!$D$43 | D9: =Premissas!$D$44 | E9: =Premissas!$D$45
B10: Delta ciclo | C10: =Premissas!$E$43 | D10: =Premissas!$E$44 | E10: =Premissas!$E$45
B11: Delta conversão (p.p.) | C11: =Premissas!$F$43 | D11: =Premissas!$F$44 | E11: =Premissas!$F$45
B13: RESULTADOS DE CENÁRIO
B14: Métrica | C14: Conservador | D14: Realista | E14: Otimista
B15: Eficiência (igual) | C15: =SUM(Motor!C41:L41) | D15: =SUM(Motor!C41:L41) | E15: =SUM(Motor!C41:L41)
B16: Ganho de ticket | C16: =N(Equipes!C29)*Premissas!$C$43*12*N(Equipes!C32)*N(Motor!C34)+N(Equipes!D29)*Premissas!$C$43*12*N(Equipes!D32)*N(Motor!D34)+N(Equipes!E29)*Premissas!$C$43*12*N(Equipes!E32)*N(Motor!E34)+N(Equipes!F29)*Premissas!$C$43*12*N(Equipes!F32)*N(Motor!F34)+N(Equipes!G29)*Premissas!$C$43*12*N(Equipes!G32)*N(Motor!G34)+N(Equipes!H29)*Premissas!$C$43*12*N(Equipes!H32)*N(Motor!H34)+N(Equipes!I29)*Premissas!$C$43*12*N(Equipes!I32)*N(Motor!I34)+N(Equipes!J29)*Premissas!$C$43*12*N(Equipes!J32)*N(Motor!J34)+N(Equipes!K29)*Premissas!$C$43*12*N(Equipes!K32)*N(Motor!K34)+N(Equipes!L29)*Premissas!$C$43*12*N(Equipes!L32)*N(Motor!L34) | D16: =N(Equipes!C29)*Premissas!$C$44*12*N(Equipes!C32)*N(Motor!C34)+N(Equipes!D29)*Premissas!$C$44*12*N(Equipes!D32)*N(Motor!D34)+N(Equipes!E29)*Premissas!$C$44*12*N(Equipes!E32)*N(Motor!E34)+N(Equipes!F29)*Premissas!$C$44*12*N(Equipes!F32)*N(Motor!F34)+N(Equipes!G29)*Premissas!$C$44*12*N(Equipes!G32)*N(Motor!G34)+N(Equipes!H29)*Premissas!$C$44*12*N(Equipes!H32)*N(Motor!H34)+N(Equipes!I29)*Premissas!$C$44*12*N(Equipes!I32)*N(Motor!I34)+N(Equipes!J29)*Premissas!$C$44*12*N(Equipes!J32)*N(Motor!J34)+N(Equipes!K29)*Premissas!$C$44*12*N(Equipes!K32)*N(Motor!K34)+N(Equipes!L29)*Premissas!$C$44*12*N(Equipes!L32)*N(Motor!L34) | E16: =N(Equipes!C29)*Premissas!$C$45*12*N(Equipes!C32)*N(Motor!C34)+N(Equipes!D29)*Premissas!$C$45*12*N(Equipes!D32)*N(Motor!D34)+N(Equipes!E29)*Premissas!$C$45*12*N(Equipes!E32)*N(Motor!E34)+N(Equipes!F29)*Premissas!$C$45*12*N(Equipes!F32)*N(Motor!F34)+N(Equipes!G29)*Premissas!$C$45*12*N(Equipes!G32)*N(Motor!G34)+N(Equipes!H29)*Premissas!$C$45*12*N(Equipes!H32)*N(Motor!H34)+N(Equipes!I29)*Premissas!$C$45*12*N(Equipes!I32)*N(Motor!I34)+N(Equipes!J29)*Premissas!$C$45*12*N(Equipes!J32)*N(Motor!J34)+N(Equipes!K29)*Premissas!$C$45*12*N(Equipes!K32)*N(Motor!K34)+N(Equipes!L29)*Premissas!$C$45*12*N(Equipes!L32)*N(Motor!L34)
B17: Margem de rampa | C17: =N(Equipes!C35)*Premissas!$D$43*N(Motor!C22)*N(Equipes!C36)*N(Equipes!C32)*Premissas!$C$12*N(Motor!C34)+N(Equipes!D35)*Premissas!$D$43*N(Motor!D22)*N(Equipes!D36)*N(Equipes!D32)*Premissas!$C$12*N(Motor!D34)+N(Equipes!E35)*Premissas!$D$43*N(Motor!E22)*N(Equipes!E36)*N(Equipes!E32)*Premissas!$C$12*N(Motor!E34)+N(Equipes!F35)*Premissas!$D$43*N(Motor!F22)*N(Equipes!F36)*N(Equipes!F32)*Premissas!$C$12*N(Motor!F34)+N(Equipes!G35)*Premissas!$D$43*N(Motor!G22)*N(Equipes!G36)*N(Equipes!G32)*Premissas!$C$12*N(Motor!G34)+N(Equipes!H35)*Premissas!$D$43*N(Motor!H22)*N(Equipes!H36)*N(Equipes!H32)*Premissas!$C$12*N(Motor!H34)+N(Equipes!I35)*Premissas!$D$43*N(Motor!I22)*N(Equipes!I36)*N(Equipes!I32)*Premissas!$C$12*N(Motor!I34)+N(Equipes!J35)*Premissas!$D$43*N(Motor!J22)*N(Equipes!J36)*N(Equipes!J32)*Premissas!$C$12*N(Motor!J34)+N(Equipes!K35)*Premissas!$D$43*N(Motor!K22)*N(Equipes!K36)*N(Equipes!K32)*Premissas!$C$12*N(Motor!K34)+N(Equipes!L35)*Premissas!$D$43*N(Motor!L22)*N(Equipes!L36)*N(Equipes!L32)*Premissas!$C$12*N(Motor!L34) | D17: =N(Equipes!C35)*Premissas!$D$44*N(Motor!C22)*N(Equipes!C36)*N(Equipes!C32)*Premissas!$C$12*N(Motor!C34)+N(Equipes!D35)*Premissas!$D$44*N(Motor!D22)*N(Equipes!D36)*N(Equipes!D32)*Premissas!$C$12*N(Motor!D34)+N(Equipes!E35)*Premissas!$D$44*N(Motor!E22)*N(Equipes!E36)*N(Equipes!E32)*Premissas!$C$12*N(Motor!E34)+N(Equipes!F35)*Premissas!$D$44*N(Motor!F22)*N(Equipes!F36)*N(Equipes!F32)*Premissas!$C$12*N(Motor!F34)+N(Equipes!G35)*Premissas!$D$44*N(Motor!G22)*N(Equipes!G36)*N(Equipes!G32)*Premissas!$C$12*N(Motor!G34)+N(Equipes!H35)*Premissas!$D$44*N(Motor!H22)*N(Equipes!H36)*N(Equipes!H32)*Premissas!$C$12*N(Motor!H34)+N(Equipes!I35)*Premissas!$D$44*N(Motor!I22)*N(Equipes!I36)*N(Equipes!I32)*Premissas!$C$12*N(Motor!I34)+N(Equipes!J35)*Premissas!$D$44*N(Motor!J22)*N(Equipes!J36)*N(Equipes!J32)*Premissas!$C$12*N(Motor!J34)+N(Equipes!K35)*Premissas!$D$44*N(Motor!K22)*N(Equipes!K36)*N(Equipes!K32)*Premissas!$C$12*N(Motor!K34)+N(Equipes!L35)*Premissas!$D$44*N(Motor!L22)*N(Equipes!L36)*N(Equipes!L32)*Premissas!$C$12*N(Motor!L34) | E17: =N(Equipes!C35)*Premissas!$D$45*N(Motor!C22)*N(Equipes!C36)*N(Equipes!C32)*Premissas!$C$12*N(Motor!C34)+N(Equipes!D35)*Premissas!$D$45*N(Motor!D22)*N(Equipes!D36)*N(Equipes!D32)*Premissas!$C$12*N(Motor!D34)+N(Equipes!E35)*Premissas!$D$45*N(Motor!E22)*N(Equipes!E36)*N(Equipes!E32)*Premissas!$C$12*N(Motor!E34)+N(Equipes!F35)*Premissas!$D$45*N(Motor!F22)*N(Equipes!F36)*N(Equipes!F32)*Premissas!$C$12*N(Motor!F34)+N(Equipes!G35)*Premissas!$D$45*N(Motor!G22)*N(Equipes!G36)*N(Equipes!G32)*Premissas!$C$12*N(Motor!G34)+N(Equipes!H35)*Premissas!$D$45*N(Motor!H22)*N(Equipes!H36)*N(Equipes!H32)*Premissas!$C$12*N(Motor!H34)+N(Equipes!I35)*Premissas!$D$45*N(Motor!I22)*N(Equipes!I36)*N(Equipes!I32)*Premissas!$C$12*N(Motor!I34)+N(Equipes!J35)*Premissas!$D$45*N(Motor!J22)*N(Equipes!J36)*N(Equipes!J32)*Premissas!$C$12*N(Motor!J34)+N(Equipes!K35)*Premissas!$D$45*N(Motor!K22)*N(Equipes!K36)*N(Equipes!K32)*Premissas!$C$12*N(Motor!K34)+N(Equipes!L35)*Premissas!$D$45*N(Motor!L22)*N(Equipes!L36)*N(Equipes!L32)*Premissas!$C$12*N(Motor!L34)
B18: Ganho de conversão | C18: =IFERROR((N(Equipes!C29)/N(Equipes!C30))/N(Motor!C47)*Premissas!$F$43/100*N(Equipes!C30)*N(Equipes!C32)*12*Premissas!$C$14*N(Motor!C34),0)+IFERROR((N(Equipes!D29)/N(Equipes!D30))/N(Motor!D47)*Premissas!$F$43/100*N(Equipes!D30)*N(Equipes!D32)*12*Premissas!$C$14*N(Motor!D34),0)+IFERROR((N(Equipes!E29)/N(Equipes!E30))/N(Motor!E47)*Premissas!$F$43/100*N(Equipes!E30)*N(Equipes!E32)*12*Premissas!$C$14*N(Motor!E34),0)+IFERROR((N(Equipes!F29)/N(Equipes!F30))/N(Motor!F47)*Premissas!$F$43/100*N(Equipes!F30)*N(Equipes!F32)*12*Premissas!$C$14*N(Motor!F34),0)+IFERROR((N(Equipes!G29)/N(Equipes!G30))/N(Motor!G47)*Premissas!$F$43/100*N(Equipes!G30)*N(Equipes!G32)*12*Premissas!$C$14*N(Motor!G34),0)+IFERROR((N(Equipes!H29)/N(Equipes!H30))/N(Motor!H47)*Premissas!$F$43/100*N(Equipes!H30)*N(Equipes!H32)*12*Premissas!$C$14*N(Motor!H34),0)+IFERROR((N(Equipes!I29)/N(Equipes!I30))/N(Motor!I47)*Premissas!$F$43/100*N(Equipes!I30)*N(Equipes!I32)*12*Premissas!$C$14*N(Motor!I34),0)+IFERROR((N(Equipes!J29)/N(Equipes!J30))/N(Motor!J47)*Premissas!$F$43/100*N(Equipes!J30)*N(Equipes!J32)*12*Premissas!$C$14*N(Motor!J34),0)+IFERROR((N(Equipes!K29)/N(Equipes!K30))/N(Motor!K47)*Premissas!$F$43/100*N(Equipes!K30)*N(Equipes!K32)*12*Premissas!$C$14*N(Motor!K34),0)+IFERROR((N(Equipes!L29)/N(Equipes!L30))/N(Motor!L47)*Premissas!$F$43/100*N(Equipes!L30)*N(Equipes!L32)*12*Premissas!$C$14*N(Motor!L34),0) | D18: =IFERROR((N(Equipes!C29)/N(Equipes!C30))/N(Motor!C47)*Premissas!$F$44/100*N(Equipes!C30)*N(Equipes!C32)*12*Premissas!$C$14*N(Motor!C34),0)+IFERROR((N(Equipes!D29)/N(Equipes!D30))/N(Motor!D47)*Premissas!$F$44/100*N(Equipes!D30)*N(Equipes!D32)*12*Premissas!$C$14*N(Motor!D34),0)+IFERROR((N(Equipes!E29)/N(Equipes!E30))/N(Motor!E47)*Premissas!$F$44/100*N(Equipes!E30)*N(Equipes!E32)*12*Premissas!$C$14*N(Motor!E34),0)+IFERROR((N(Equipes!F29)/N(Equipes!F30))/N(Motor!F47)*Premissas!$F$44/100*N(Equipes!F30)*N(Equipes!F32)*12*Premissas!$C$14*N(Motor!F34),0)+IFERROR((N(Equipes!G29)/N(Equipes!G30))/N(Motor!G47)*Premissas!$F$44/100*N(Equipes!G30)*N(Equipes!G32)*12*Premissas!$C$14*N(Motor!G34),0)+IFERROR((N(Equipes!H29)/N(Equipes!H30))/N(Motor!H47)*Premissas!$F$44/100*N(Equipes!H30)*N(Equipes!H32)*12*Premissas!$C$14*N(Motor!H34),0)+IFERROR((N(Equipes!I29)/N(Equipes!I30))/N(Motor!I47)*Premissas!$F$44/100*N(Equipes!I30)*N(Equipes!I32)*12*Premissas!$C$14*N(Motor!I34),0)+IFERROR((N(Equipes!J29)/N(Equipes!J30))/N(Motor!J47)*Premissas!$F$44/100*N(Equipes!J30)*N(Equipes!J32)*12*Premissas!$C$14*N(Motor!J34),0)+IFERROR((N(Equipes!K29)/N(Equipes!K30))/N(Motor!K47)*Premissas!$F$44/100*N(Equipes!K30)*N(Equipes!K32)*12*Premissas!$C$14*N(Motor!K34),0)+IFERROR((N(Equipes!L29)/N(Equipes!L30))/N(Motor!L47)*Premissas!$F$44/100*N(Equipes!L30)*N(Equipes!L32)*12*Premissas!$C$14*N(Motor!L34),0) | E18: =IFERROR((N(Equipes!C29)/N(Equipes!C30))/N(Motor!C47)*Premissas!$F$45/100*N(Equipes!C30)*N(Equipes!C32)*12*Premissas!$C$14*N(Motor!C34),0)+IFERROR((N(Equipes!D29)/N(Equipes!D30))/N(Motor!D47)*Premissas!$F$45/100*N(Equipes!D30)*N(Equipes!D32)*12*Premissas!$C$14*N(Motor!D34),0)+IFERROR((N(Equipes!E29)/N(Equipes!E30))/N(Motor!E47)*Premissas!$F$45/100*N(Equipes!E30)*N(Equipes!E32)*12*Premissas!$C$14*N(Motor!E34),0)+IFERROR((N(Equipes!F29)/N(Equipes!F30))/N(Motor!F47)*Premissas!$F$45/100*N(Equipes!F30)*N(Equipes!F32)*12*Premissas!$C$14*N(Motor!F34),0)+IFERROR((N(Equipes!G29)/N(Equipes!G30))/N(Motor!G47)*Premissas!$F$45/100*N(Equipes!G30)*N(Equipes!G32)*12*Premissas!$C$14*N(Motor!G34),0)+IFERROR((N(Equipes!H29)/N(Equipes!H30))/N(Motor!H47)*Premissas!$F$45/100*N(Equipes!H30)*N(Equipes!H32)*12*Premissas!$C$14*N(Motor!H34),0)+IFERROR((N(Equipes!I29)/N(Equipes!I30))/N(Motor!I47)*Premissas!$F$45/100*N(Equipes!I30)*N(Equipes!I32)*12*Premissas!$C$14*N(Motor!I34),0)+IFERROR((N(Equipes!J29)/N(Equipes!J30))/N(Motor!J47)*Premissas!$F$45/100*N(Equipes!J30)*N(Equipes!J32)*12*Premissas!$C$14*N(Motor!J34),0)+IFERROR((N(Equipes!K29)/N(Equipes!K30))/N(Motor!K47)*Premissas!$F$45/100*N(Equipes!K30)*N(Equipes!K32)*12*Premissas!$C$14*N(Motor!K34),0)+IFERROR((N(Equipes!L29)/N(Equipes!L30))/N(Motor!L47)*Premissas!$F$45/100*N(Equipes!L30)*N(Equipes!L32)*12*Premissas!$C$14*N(Motor!L34),0)
B19: Ganho de ciclo | C19: =SUM(Motor!C68:L68) | D19: =IF(Motor!C15,IF(AND(N(Motor!C52)>0,N(Equipes!C46)>0),MIN(IF(AND(D10>0,D10<1),(Equipes!C29/Equipes!C30)*(1/(1-D10)-1),0),MAX(0,Equipes!C46-(Equipes!C29/Equipes!C30)/Motor!C47)*Motor!C47)*Equipes!C30*Equipes!C32*12*Premissas!$C$13*Motor!C34,0),"") | E19: =IF(Motor!C15,IF(AND(N(Motor!C52)>0,N(Equipes!C46)>0),MIN(IF(AND(E10>0,E10<1),(Equipes!C29/Equipes!C30)*(1/(1-E10)-1),0),MAX(0,Equipes!C46-(Equipes!C29/Equipes!C30)/Motor!C47)*Motor!C47)*Equipes!C30*Equipes!C32*12*Premissas!$C$13*Motor!C34,0),"")
B20: VALOR ANUAL TOTAL | C20: =SUM(C15:C19) | D20: =SUM(D15:D19) | E20: =SUM(E15:E19)
B21: Mensalidade | C21: =Conta!$C$22 | D21: =Conta!$C$22 | E21: =Conta!$C$22
B22: Investimento anual | C22: =Conta!$C$26 | D22: =Conta!$C$26 | E22: =Conta!$C$26
B23: ROI | C23: =IF(AND(ISNUMBER(C20),N(C22)>0),C20/C22,"") | D23: =IF(AND(ISNUMBER(D20),N(D22)>0),D20/D22,"") | E23: =IF(AND(ISNUMBER(E20),N(E22)>0),E20/E22,"")
B24: Payback (meses) | C24: =IF(AND(ISNUMBER(C22),N(C20)>0),C22/C20*12,"") | D24: =IF(AND(ISNUMBER(D22),N(D20)>0),D22/D20*12,"") | E24: =IF(AND(ISNUMBER(E22),N(E20)>0),E22/E20*12,"")
